Workbook

Sheet Содержание
B2: Содержание | E2: 2025 год-2026 год
B3: Легковые автомобили | E3: стоимость общая | F3: стоимость запасных частей | G3: стоимость работ
B4: 1 | C4: Н 481 ОУ 797 | D4: LADA 4X4 | E4: =нива!E11 -> 0 | F4: =нива!F11 -> 0 | G4: =нива!G11 -> 0
B5: 2 | C5: О 522 МЕ 797 | D5: SKODA Octavia | E5: =шкода!E11 -> 16350 | F5: =шкода!F11 -> 10750 | G5: =шкода!G11 -> 5600
B6: 3 | C6: А 497 АС 799 | D6: TOYOTA Camry | E6: =Camry!E12 -> 200290 | F6: =Camry!F12 -> 99350 | G6: =Camry!G12 -> 100940
B7: 5 | C7: O 002 HE 197 | D7: TOYOTA LAND CRUISER 200 | E7: =ЛК002!E11 -> 26900 | F7: =ЛК002!F11 -> 26900 | G7: =ЛК002!G11 -> 0
B8: 6 | C8: Х 316 ОЕ 797 | D8: GEELY MONJARO | E8: =Geely!E11 -> 0 | F8: =Geely!F11 -> 0 | G8: =Geely!G11 -> 0
B9: 7 | C9: К 384 ОА 797 | D9: HAVAL DARGO | E9: =Haval!E11 -> 42370 | F9: =Haval!F11 -> 36630 | G9: =Haval!G11 -> 5740
B10: 8 | C10: Н 078 АМ 977 | D10: Land Rover RANGE ROVER | E10: ='LR-RR '!E11 -> 0 | F10: ='LR-RR '!F11 -> 0 | G10: ='LR-RR '!G11 -> 0
B11: 10 | C11: А 026 ХС 799 | D11: Volkswagen CADDY | E11: ='VW '!E11 -> 163221 | F11: ='VW '!F11 -> 106500 | G11: ='VW '!G11 -> 56721
B12: 11 | C12: Е 881 ТО 790 | D12: Kia Sportage | E12: =Kia!E11 -> 8336.9 | F12: =Kia!F11 -> 8336.9 | G12: =Kia!G11 -> 0
B13: Малотоннажные автомобили
B14: 1 | C14: Е 789 ТУ 799 | D14: ГАЗ А22R32 (грузовой бортовой) | E14: ='Г 789'!E11 -> 0 | F14: ='Г 789'!F11 -> 0 | G14: ='Г 789'!G11 -> 0
B15: 2 | C15: Т 171 СС 750 | D15: ГАЗ-А22R32 Платформа с каркасом и тентом | E15: ='Г 171'!E11 -> 33650 | F15: ='Г 171'!F11 -> 33650 | G15: ='Г 171'!G11 -> 0
B16: 3 | C16: В 456 АО 797 | D16: ГАЗ-A22R32 (грузовой с ботром) | E16: ='Г 456'!E12 -> 33400 | F16: ='Г 456'!F12 -> 33400 | G16: ='Г 456'!G12 -> 0
B17: 4 | C17: Н 900 В0 977 | D17: Газель GAZelle NEXT | E17: ='Г 900'!E11 -> 10000 | F17: ='Г 900'!F11 -> 0 | G17: ='Г 900'!G11 -> 10000
B18: 5 | C18: Т 189 УВ 777 | D18: ГАЗ 2705 (грузовой цельнометалический 6 п/мест) | E18: ='Г 189'!E11 -> 164670 | F18: ='Г 189'!F11 -> 164670 | G18: ='Г 189'!G11 -> 0
B19: 6 | C19: С 982 ОА 797 | D19: ГАЗ 2705 грузовой фургон | E19: ='Г 982'!E11 -> 0 | F19: ='Г 982'!F11 -> 0 | G19: ='Г 982'!G11 -> 0
B20: 7 | C20: O 503 PT 777 | D20: ГАЗ-А22R32 (грузовой бортовой) | E20: ='Г 503'!E11 -> 110088.56 | F20: ='Г 503'!F11 -> 47378.56 | G20: ='Г 503'!G11 -> 62710
B21: 8 | C21: О 035 КН 799 | D21: 278865 (бортовая платформа) | E21: ='Г 035'!E11 -> 0 | F21: ='Г 035'!F11 -> 0 | G21: ='Г 035'!G11 -> 0
B22: 9 | C22: У 479 MC 797 | D22: Ford Transit (техпомощь) | E22: ='FT 479'!E11 -> 130801.61 | F22: ='FT 479'!F11 -> 115801.61 | G22: ='FT 479'!G11 -> 15000
B23: 10 | C23: У 978 ММ 797 | D23: Ford Transit 22278С (авт-ль грузопассажирский) | E23: ='FT 978'!E11 -> 0 | F23: ='FT 978'!F11 -> 0 | G23: ='FT 978'!G11 -> 0
B24: 11 | C24: Е 335 ВК 977 | D24: Ford Transit 3227AR двойная кабина (БОРТОВАЯ ПЛАТФОРМА) | E24: ='FT 335'!E11 -> 0 | F24: ='FT 335'!F11 -> 0 | G24: ='FT 335'!G11 -> 0
B25: 12 | C25: Е 344 ВК 977 | D25: Ford Transit 3227AR двойная кабина | E25: ='FT 344'!E11 -> 12230 | F25: ='FT 344'!F11 -> 4230 | G25: ='FT 344'!G11 -> 8000
B26: Автобусы
B27: 1 | C27: Х 908 УК 799 | D27: Газель GAZellIe NN | E27: ='Г 908'!E11 -> 0 | F27: ='Г 908'!F11 -> 0 | G27: ='Г 908'!G11 -> 0
B28: 2 | C28: Н 680 В0 977 | D28: Ford Transit | E28: ='FT 680'!E11 -> 0 | F28: ='FT 680'!F11 -> 0 | G28: ='FT 680'!G11 -> 0
B29: 3 | C29: А 382 МН 797 | D29: FORD Transit (Автобус) | E29: ='FT 390'!E16 -> 106460.94 | F29: ='FT 390'!F16 -> 74460.94 | G29: ='FT 390'!G16 -> 32000
B30: Специальные автомобили
B31: 1 | C31: Н 152 ЕТ 977 | D31: Специальный, грузовой бортовой оснащенный краном-манипулятором TH-T13 FOTON 3006A7Н | E31: =Foton!E11 -> 20896.6 | F31: =Foton!F11 -> 20896.6 | G31: =Foton!G11 -> 0
B32: 2 | C32: М 711 ХУ 799 | D32: Специальная Комбинированная дорожная машина КО-806-01 | E32: =КО!E11 -> 80100 | F32: =КО!F11 -> 15100 | G32: =КО!G11 -> 65000
B33: 3 | C33: Н 421 УА 799 | D33: Специальный Автогудронатор РЕГИОН 45 АС-С41R | E33: =Гудронатор!E11 -> 736.84 | F33: =Гудронатор!F11 -> 736.84 | G33: =Гудронатор!G11 -> 0
B34: Грузовые-самосвалы
B35: 1 | C35: К 877 ТУ 799 | D35: Автосамосвал КАМАЗ К3340 6520-53 | E35: ='К 877'!E17 -> 195843 | F35: ='К 877'!F17 -> 84993 | G35: ='К 877'!G17 -> 110850
B36: 2 | C36: К 927 ТУ 799 | D36: Автосамосвал КАМАЗ К3340 6520-53 | E36: ='К 927'!E20 -> 541748 | F36: ='К 927'!F20 -> 247050 | G36: ='К 927'!G20 -> 294698
B37: 3 | C37: К 983 ТУ 799 | D37: Автосамосвал КАМАЗ К3340 6520-53 | E37: ='К 983'!E21 -> 1548983 | F37: ='К 983'!F21 -> 362923 | G37: ='К 983'!G21 -> 1186060
B38: 4 | C38: К 994 ТУ 799 | D38: Автосамосвал КАМАЗ К3340 6520-53 | E38: ='К 994'!E21 -> 267820 | F38: ='К 994'!F21 -> 179020 | G38: ='К 994'!G21 -> 121800
B39: 5 | C39: Н 487 АА 977 | D39: Автосамосвал КАМАЗ К3340 6520-53 | E39: ='К 487'!E11 -> 189997 | F39: ='К 487'!F11 -> 59997 | G39: ='К 487'!G11 -> 130000
B40: 6 | C40: Х 152 НО 799 | D40: Самосвал SHACMAN SX3256DR384 | E40: ='SH 152'!E18 -> 301751 | F40: ='SH 152'!F18 -> 23751 | G40: ='SH 152'!G18 -> 278000
B41: 7 | C41: 320 | D41: Самосвал SHACMAN SX3256DR384 | E41: ='К 320'!E11 -> 188661 | F41: ='К 320'!F11 -> 54971 | G41: ='К 320'!G11 -> 133690
...

Sheet нива
A1: Содержание!A1
B3: Н 481 ОУ 797 | C3: XTA212140R2478441 | D3: LADA 4X4 | E3: 2023
A5: Дата документа | B5: номер документа | C5: поставщик | D5: вид работ | E5: стоимость общая | F5: стоимость запасных частей | G5: стоимость работ
E6: =SUM(F6:G6) -> 0
E7: =SUM(F7:G7) -> 0
E8: =SUM(F8:G8) -> 0
E9: =SUM(F9:G9) -> 0
E10: =SUM(F10:G10) -> 0
A11: Итого | E11: =SUM(F11:G11) -> 0 | F11: =SUM(F6:F10) -> 0 | G11: =SUM(G6:G10) -> 0

Sheet шкода
A1: Содержание!A1
B3: О 522 МЕ 797 | C3: XW8AN6NX5MH064819 | D3: SKODA Octavia | E3: 2021
A5: Дата документа | B5: номер документа | C5: поставщик | D5: вид работ | E5: стоимость общая | F5: стоимость запасных частей | G5: стоимость работ
A6: 46066 | B6: 2030976 | C6: Другой сервис | D6: ТО | E6: =SUM(F6:G6) -> 16350 | F6: 10750 | G6: 5600
E7: =SUM(F7:G7) -> 0
E8: =SUM(F8:G8) -> 0
E9: =SUM(F9:G9) -> 0
E10: =SUM(F10:G10) -> 0
A11: Итого | E11: =SUM(F11:G11) -> 16350 | F11: =SUM(F6:F10) -> 10750 | G11: =SUM(G6:G10) -> 5600

Sheet Camry
A1: Содержание!A1
B3: А 497 АС 799 | C3: XW7BF4FK10S157489 | D3: TOYOTA Camry | E3: 2017
A5: Дата документа | B5: номер документа | C5: поставщик | D5: вид работ | E5: стоимость общая | F5: стоимость запасных частей | G5: стоимость работ
A6: 45701 | B6: DHAU1904145 | C6: Другой сервис | D6: ремонт АКПП | E6: =SUM(F6:G6) -> 200290 | F6: 99350 | G6: 100940
E7: =SUM(F7:G7) -> 0
E8: =SUM(F8:G8) -> 0
E9: =SUM(F9:G9) -> 0
E10: =SUM(F10:G10) -> 0
E11: =SUM(F11:G11) -> 0
A12: Итого | E12: =SUM(F12:G12) -> 200290 | F12: =SUM(F6:F11) -> 99350 | G12: =SUM(G6:G11) -> 100940

Sheet ЛК002
A1: Содержание!A1
B3: O 002 HE 197 | C3: JTMCV02J504298364 | D3: TOYOTA LAND CRUISER 200 | E3: 2019
A5: Дата документа | B5: номер документа | C5: поставщик | D5: вид работ | E5: стоимость общая | F5: стоимость запасных частей | G5: стоимость работ
A6: 45693 | B6: DHAU1903830 | C6: Другой сервис | D6: ТО | E6: =SUM(F6:G6) -> 26900 | F6: 26900
E7: =SUM(F7:G7) -> 0
E8: =SUM(F8:G8) -> 0
E9: =SUM(F9:G9) -> 0
E10: =SUM(F10:G10) -> 0
A11: Итого | E11: =SUM(F11:G11) -> 26900 | F11: =SUM(F6:F10) -> 26900 | G11: =SUM(G6:G10) -> 0

Sheet Geely
A1: Содержание!A1
B3: Х 316 ОЕ 797 | C3: LB37852D3PS129584 | D3: GEELY MONJARO | E3: 2023
A5: Дата документа | B5: номер документа | C5: поставщик | D5: вид работ | E5: стоимость общая | F5: стоимость запасных частей | G5: стоимость работ
E6: =SUM(F6:G6) -> 0
E7: =SUM(F7:G7) -> 0
E8: =SUM(F8:G8) -> 0
E9: =SUM(F9:G9) -> 0
E10: =SUM(F10:G10) -> 0
A11: Итого | E11: =SUM(E6:E10) -> 0 | F11: =SUM(F6:F10) -> 0 | G11: =SUM(G6:G10) -> 0

Sheet Haval
A1: Содержание!A1
B3: К 384 ОА 797 | C3: LGWFF6А53PH938163 | D3: HAVAL DARGO | E3: 2023
A5: Дата документа | B5: номер документа | C5: поставщик | D5: вид работ | E5: стоимость общая | F5: стоимость запасных частей | G5: стоимость работ
A6: 45685 | B6: DHAU1896365 | C6: Другой Сервис | D6: ТО | E6: =SUM(F6:G6) -> 42370 | F6: 36630 | G6: 5740
E7: =SUM(F7:G7) -> 0
E8: =SUM(F8:G8) -> 0
E9: =SUM(F9:G9) -> 0
E10: =SUM(F10:G10) -> 0
A11: Итого | E11: =SUM(E6:E10) -> 42370 | F11: =SUM(F6:F10) -> 36630 | G11: =SUM(G6:G10) -> 5740

Sheet LR-RR 
A1: Содержание!A1
B3: Н 078 АМ 977 | C3: SALGA3JF9GA251001 | D3: Land Rover RANGE ROVER | E3: 2015
A5: Дата документа | B5: номер документа | C5: поставщик | D5: вид работ | E5: стоимость общая | F5: стоимость запасных частей | G5: стоимость работ
E6: =SUM(F6:G6) -> 0
E7: =SUM(F7:G7) -> 0
E8: =SUM(F8:G8) -> 0
E9: =SUM(F9:G9) -> 0
E10: =SUM(F10:G10) -> 0
A11: Итого | E11: =SUM(E6:E10) -> 0 | F11: =SUM(F6:F10) -> 0 | G11: =SUM(G6:G10) -> 0

Sheet VW 
A1: Содержание!A1
B3: А 026 ХС 799 | C3: WV1ZZZ2KZEX098108 | D3: Volkswagen CADDY
A5: Дата документа | B5: номер документа | C5: поставщик | D5: вид работ | E5: стоимость общая | F5: стоимость запасных частей | G5: стоимость работ
A6: 45678 | B6: DHAU1898109 | C6: ООО Другой сервис | D6: ТО и ремонт | E6: =SUM(F6:G6) -> 92520 | F6: 79220 | G6: 13300
A7: 46066 | B7: DHAU2029374 | C7: ООО Другой сервис | D7: ТО и ремонт | E7: =SUM(F7:G7) -> 44780 | F7: 27280 | G7: 17500
A8: 46099 | B8: 17620012410 | C8: Авторусь Ритейл | D8: зпмена интеркулера | E8: =SUM(F8:G8) -> 25921 | G8: 25921
E9: =SUM(F9:G9) -> 0
E10: =SUM(F10:G10) -> 0
A11: Итого | E11: =SUM(E6:E10) -> 163221 | F11: =SUM(F6:F10) -> 106500 | G11: =SUM(G6:G10) -> 56721

Sheet Kia
A1: Содержание!A1
B3: Е 881 ТО 790 | C3: XWEPC811DC0010139 | D3: Kia Sportage | E3: 2011
A5: Дата документа | B5: номер документа | C5: поставщик | D5: вид работ | E5: стоимость общая | F5: стоимость запасных частей | G5: стоимость работ
A6: 45720 | B6: 040325-6110 | C6: ФА Логистик | D6: АКБ | E6: =SUM(F6:G6) -> 8336.9 | F6: 8336.9
E7: =SUM(F7:G7) -> 0
E8: =SUM(F8:G8) -> 0
E9: =SUM(F9:G9) -> 0
E10: =SUM(F10:G10) -> 0
A11: Итого | E11: =SUM(E6:E10) -> 8336.9 | F11: =SUM(F6:F10) -> 8336.9 | G11: =SUM(G6:G10) -> 0

Sheet Г 035
A1: Содержание!A1
B3: О 035 КН 799 | C3: X8B278865J0018642 | D3: 278865 (бортовая платформа) | E3: 2018
A5: Дата документа | B5: номер документа | C5: поставщик | D5: вид работ | E5: стоимость общая | F5: стоимость запасных частей | G5: стоимость работ
E6: =SUM(F6:G6) -> 0
E7: =SUM(F7:G7) -> 0
E8: =SUM(F8:G8) -> 0
E9: =SUM(F9:G9) -> 0
E10: =SUM(F10:G10) -> 0
A11: Итого | E11: =SUM(E6:E10) -> 0 | F11: =SUM(F6:F10) -> 0 | G11: =SUM(G6:G10) -> 0

Sheet Г 171
A1: Содержание!A1
B3: Т 171 СС 750 | C3: X96A22R32E2582297 | D3: ГАЗ-А22R32 Платформа с каркасом и тентом | E3: 2014
A5: Дата документа | B5: номер документа | C5: поставщик | D5: вид работ | E5: стоимость общая | F5: стоимость запасных частей | G5: стоимость работ
A6: 46197 | B6: 11 | C6: ИП Ашуров | D6: запчасти | E6: =SUM(F6:G6) -> 33650 | F6: 33650
E7: =SUM(F7:G7) -> 0
E8: =SUM(F8:G8) -> 0
E9: =SUM(F9:G9) -> 0
E10: =SUM(F10:G10) -> 0
A11: Итого | E11: =SUM(E6:E10) -> 33650 | F11: =SUM(F6:F10) -> 33650 | G11: =SUM(G6:G10) -> 0

Sheet Г 456
A1: Содержание!A1
B3: В 456 АО 797 | C3: Х96A22R32E2580173 | D3: ГАЗ-A22R32 (грузовой с ботром) | E3: 2014
A5: Дата документа | B5: номер документа | C5: поставщик | D5: вид работ | E5: стоимость общая | F5: стоимость запасных частей | G5: стоимость работ
A6: 46195 | B6: 10 | C6: ИП Ашуров | D6: запчасти после ДТП | E6: =SUM(F6:G6) -> 33400 | F6: 33400 | K6: 32654654 | L6: 25000 | M6: 4565461 | N6: 26500
E7: =SUM(F7:G7) -> 0
E8: =SUM(F8:G8) -> 0
E9: =SUM(F9:G9) -> 0
E10: =SUM(F10:G10) -> 0
E11: =SUM(F11:G11) -> 0
A12: Итого | E12: =SUM(E6:E11) -> 33400 | F12: =SUM(F6:F11) -> 33400 | G12: =SUM(G6:G11) -> 0

Sheet Г 189
A1: Содержание!A1
B3: Т 189 УВ 777 | C3: Х96270500В0697236 | D3: ГАЗ 2705 (грузовой цельнометалический 6 п/мест) | E3: 2011
A5: Дата документа | B5: номер документа | C5: поставщик | D5: вид работ | E5: стоимость общая | F5: стоимость запасных частей | G5: стоимость работ
A6: 46064 | B6: 552\4 | C6: Т-запчасть | D6: диск тормозной, колодки | E6: =SUM(F6:G6) -> 11761 | F6: 11761
A7: 46053 | B7: 6 | C7: ИП Ашуров | D7: КПП | E7: =SUM(F7:G7) -> 65000 | F7: 65000
A8: 46077 | B8: 750\4 | C8: Т-запчасть | D8: вакуум, суппорт мелочевка | E8: =SUM(F8:G8) -> 27909 | F8: 27909
A9: 46062 | B9: ТН 8 | C9: ИП Ашуров | D9: автошины к-т | E9: =SUM(F9:G9) -> 60000 | F9: 60000
E10: =SUM(F10:G10) -> 0
A11: Итого | E11: =SUM(E6:E10) -> 164670 | F11: =SUM(F6:F10) -> 164670 | G11: =SUM(G6:G10) -> 0

Sheet Г 503
A1: Содержание!A1
B3: O 503 PT 777 | C3: X96A22R32G2652087 | D3: ГАЗ-А22R32 (грузовой бортовой) | E3: 2016
A5: Дата документа | B5: номер документа | C5: поставщик | D5: вид работ | E5: стоимость общая | F5: стоимость запасных частей | G5: стоимость работ
A6: 45702 | B6: 15С | C6: ИП Устинов | D6: моторчи печки | E6: =SUM(F6:G6) -> 1880 | F6: 1880
A7: 45714 | B7: 456694067 | C7: АПР | D7: запчасти торм система | E7: =SUM(F7:G7) -> 10295.56 | F7: 10295.56
A8: 45714 | B8: 17С | C8: ИП Устинов | D8: трос ручника | E8: =SUM(F8:G8) -> 3450 | F8: 3450
A9: 45781 | B9: 143 | C9: РЕМГУД | D9: ремонт коробки | E9: =SUM(F9:G9) -> 94463 | F9: 31753 | G9: 62710
E10: =SUM(F10:G10) -> 0
A11: Итого | E11: =SUM(E6:E10) -> 110088.56 | F11: =SUM(F6:F10) -> 47378.56 | G11: =SUM(G6:G10) -> 62710

Sheet Г 789
A1: Содержание!A1
B3: Е 789 ТУ 799 | C3: Х96А22R32G2656379 | D3: ГАЗ А22R32 (грузовой бортовой) | E3: 2016
A5: Дата документа | B5: номер документа | C5: поставщик | D5: вид работ | E5: стоимость общая | F5: стоимость запасных частей | G5: стоимость работ
E6: =SUM(F6:G6) -> 0
E7: =SUM(F7:G7) -> 0
E8: =SUM(F8:G8) -> 0
E9: =SUM(F9:G9) -> 0
E10: =SUM(F10:G10) -> 0
A11: Итого | E11: =SUM(E6:E10) -> 0 | F11: =SUM(F6:F10) -> 0 | G11: =SUM(G6:G10) -> 0

Sheet Г 900
A1: Содержание!A1
B3: Н 900 В0 977 | C3: X96A32R32M0915045 | D3: Газель GAZelle NEXT | E3: 2021
A5: Дата документа | B5: номер документа | C5: поставщик | D5: вид работ | E5: стоимость общая | F5: стоимость запасных частей | G5: стоимость ремонта
A6: 46169 | B6: 40 | C6: ИП Баранов | D6: ремонт электрики | E6: =SUM(F6:G6) -> 10000 | G6: 10000
E7: =SUM(F7:G7) -> 0
E8: =SUM(F8:G8) -> 0
E9: =SUM(F9:G9) -> 0
E10: =SUM(F10:G10) -> 0
A11: Итого | E11: =SUM(E6:E10) -> 10000 | F11: =SUM(F6:F10) -> 0 | G11: =SUM(G6:G10) -> 10000

Sheet Г 908
A1: Содержание!A1
B3: Х 908 УК 799 | C3: X96A65R52N0932985 | D3: Газель GAZellIe NN | E3: 2021
A5: Дата документа | B5: номер документа | C5: поставщик | D5: вид работ | E5: стоимость общая | F5: стоимость запасных частей | G5: стоимость работ
E6: =SUM(F6:G6) -> 0
E7: =SUM(F7:G7) -> 0
E8: =SUM(F8:G8) -> 0
E9: =SUM(F9:G9) -> 0
E10: =SUM(F10:G10) -> 0
A11: Итого | E11: =SUM(E6:E10) -> 0 | F11: =SUM(F6:F10) -> 0 | G11: =SUM(G6:G10) -> 0

Sheet Г 982
A1: Содержание!A1
B3: С 982 ОА 797 | C3: Х96270500С1744419 | D3: ГАЗ 2705 грузовой фургон | E3: 2012
A5: Дата документа | B5: номер документа | C5: поставщик | D5: вид работ | E5: стоимость общая | F5: стоимость запасных частей | G5: стоимость работ
E6: =SUM(F6:G6) -> 0
E7: =SUM(F7:G7) -> 0
E8: =SUM(F8:G8) -> 0
E9: =SUM(F9:G9) -> 0
E10: =SUM(F10:G10) -> 0
A11: Итого | E11: =SUM(E6:E10) -> 0 | F11: =SUM(F6:F10) -> 0 | G11: =SUM(G6:G10) -> 0

Sheet FT 335
A1: Содержание!A1
B3: Е 335 ВК 977 | C3: XUS3227ARK0002907 | D3: Ford Transit 3227AR двойная кабина (БОРТОВАЯ ПЛАТФОРМА) | E3: 2019
A5: Дата документа | B5: номер документа | C5: поставщик | D5: вид работ | E5: стоимость общая | F5: стоимость запасных частей | G5: стоимость работ
E6: =SUM(F6:G6) -> 0
E7: =SUM(F7:G7) -> 0
E8: =SUM(F8:G8) -> 0
E9: =SUM(F9:G9) -> 0
E10: =SUM(F10:G10) -> 0
A11: Итого | E11: =SUM(E6:E10) -> 0 | F11: =SUM(F6:F10) -> 0 | G11: =SUM(G6:G10) -> 0

Sheet FT 344
A1: Содержание!A1
B3: Е 344 ВК 977 | C3: XUS3227ARK0003018 | D3: Ford Transit 3227AR двойная кабина | E3: 2019
A5: Дата документа | B5: номер документа | C5: поставщик | D5: вид работ | E5: стоимость общая | F5: стоимость запасных частей | G5: стоимость работ
A6: 45702 | B6: 16С | C6: ИП Устинов | D6: торм-е накладки | E6: =SUM(F6:G6) -> 4230 | F6: 4230
A7: 46146 | B7: В1402 | C7: Вольтаж | D7: ремонт стартера | E7: =SUM(F7:G7) -> 8000 | G7: 8000
E8: =SUM(F8:G8) -> 0
E9: =SUM(F9:G9) -> 0
E10: =SUM(F10:G10) -> 0
A11: Итого | E11: =SUM(E6:E10) -> 12230 | F11: =SUM(F6:F10) -> 4230 | G11: =SUM(G6:G10) -> 8000

Sheet FT 390
A1: Содержание!A1
B3: А 382 МН 797 | C3: Z6FXXXESGXJJ06015 | D3: FORD Transit (Автобус) | E3: 2018
A5: Дата документа | B5: номер документа | C5: поставщик | D5: вид работ | E5: стоимость общая | F5: стоимость запасных частей | G5: стоимость работ | H5: пробег
A6: 46196 | B6: 9041497338 | C6: АПР | D6: к-кт сцепления | E6: =SUM(F6:G6) -> 31924.94 | F6: 31924.94 | H6: 213557
A7: 46202 | B7: 9041754945 | C7: апр | D7: маховик и болт маховика | E7: =SUM(F7:G7) -> 42536 | F7: 42536
A8: 46232 | B8: 729-3 | C8: ИП Беспалов | D8: замена блока СКЗИ | E8: =SUM(F8:G8) -> 32000 | G8: 32000
E9: =SUM(F9:G9) -> 0
E10: =SUM(F10:G10) -> 0
E11: =SUM(F11:G11) -> 0
E12: =SUM(F12:G12) -> 0
E13: =SUM(F13:G13) -> 0
E14: =SUM(F14:G14) -> 0
E15: =SUM(F15:G15) -> 0
A16: Итого | E16: =SUM(E6:E15) -> 106460.94 | F16: =SUM(F6:F15) -> 74460.94 | G16: =SUM(G6:G15) -> 32000

Sheet FT 479
A1: Содержание!A1
B3: У 479 MC 797 | C3: X2FXXXESGXKP43412 | D3: Ford Transit (техпомощь) | E3: 2019
A5: Дата документа | B5: номер документа | C5: поставщик | D5: вид работ | E5: стоимость общая | F5: стоимость запасных частей | G5: стоимость работ | H5: пробег
A6: 46078 | B6: В0648 | C6: Вольтаж | D6: ремонт стартера | E6: =SUM(F6:G6) -> 15000 | G6: 15000
A7: 46197 | B7: 9041546465 | C7: АПР | D7: Маховик | E7: =SUM(F7:G7) -> 40372.9 | F7: 40372.9 | H7: 113700
A8: 46197 | B8: 9041546465 | C8: аПР | D8: к-кт сцепления | E8: =SUM(F8:G8) -> 31796.71 | F8: 31796.71
A9: 46085 | B9: МШ-0020722 | C9: ППР | D9: штны | E9: =SUM(F9:G9) -> 43632 | F9: 43632
E10: =SUM(F10:G10) -> 0
A11: Итого | E11: =SUM(E6:E10) -> 130801.61 | F11: =SUM(F6:F10) -> 115801.61 | G11: =SUM(G6:G10) -> 15000

Sheet FT 680
A1: Содержание!A1
B3: Н 680 В0 977 | C3: X2FXXXESGXKM42540 | D3: Ford Transit | E3: 2019
A5: Дата документа | B5: номер документа | C5: поставщик | D5: вид работ | E5: стоимость общая | F5: стоимость запасных частей | G5: стоимость работ
E7: =SUM(F7:G7) -> 0
E8: =SUM(F8:G8) -> 0
E9: =SUM(F9:G9) -> 0
E10: =SUM(F10:G10) -> 0
A11: Итого | E11: =SUM(E6:E10) -> 0 | F11: =SUM(F6:F10) -> 0 | G11: =SUM(G6:G10) -> 0

Sheet FT 978
A1: Содержание!A1
B3: У 978 ММ 797 | C3: XUS22278CG0002627 | D3: Ford Transit 22278С (авт-ль грузопассажирский) | E3: 2016
A5: Дата документа | B5: номер документа | C5: поставщик | D5: вид работ | E5: стоимость общая | F5: стоимость запасных частей | G5: стоимость работ
E6: =SUM(F6:G6) -> 0
E7: =SUM(F7:G7) -> 0
E8: =SUM(F8:G8) -> 0
E9: =SUM(F9:G9) -> 0
E10: =SUM(F10:G10) -> 0
A11: Итого | E11: =SUM(E6:E10) -> 0 | F11: =SUM(F6:F10) -> 0 | G11: =SUM(G6:G10) -> 0

Sheet Foton
A1: Содержание!A1
B3: Н 152 ЕТ 977 | C3: X89TU1T13R1GP3006 | D3: Специальный, грузовой бортовой оснащенный краном-манипулятором TH-T13 FOTON 3006A7Н | E3: 2024
A5: Дата документа | B5: номер документа | C5: поставщик | D5: вид работ | E5: стоимость общая | F5: стоимость запасных частей | G5: стоимость работ
A6: 45723 | B6: 9020098921 | C6: АПР | D6: АКБ | E6: =SUM(F6:G6) -> 20896.6 | F6: 20896.6
E7: =SUM(F7:G7) -> 0
E8: =SUM(F8:G8) -> 0
E9: =SUM(F9:G9) -> 0
E10: =SUM(F10:G10) -> 0
A11: Итого | E11: =SUM(E6:E10) -> 20896.6 | F11: =SUM(F6:F10) -> 20896.6 | G11: =SUM(G6:G10) -> 0

Sheet КО
A1: Содержание!A1
B3: М 711 ХУ 799 | C3: X5H806015M0000355 | D3: Специальная Комбинированная дорожная машина КО-806-01 | E3: 2021
A5: Дата документа | B5: номер документа | C5: поставщик | D5: вид работ | E5: стоимость общая | F5: стоимость запасных частей | G5: стоимость работ
A6: 46235 | B6: 199 | C6: АГ-Сервис | D6: ремонт ГУРа | E6: =SUM(F6:G6) -> 65000 | G6: 65000
A7: 46268 | B7: 3796\4 | C7: Т-запчасти | D7: насос ГУРа | E7: =SUM(F7:G7) -> 15100 | F7: 15100
E8: =SUM(F8:G8) -> 0
E9: =SUM(F9:G9) -> 0
E10: =SUM(F10:G10) -> 0
A11: Итого | E11: =SUM(E6:E10) -> 80100 | F11: =SUM(F6:F10) -> 15100 | G11: =SUM(G6:G10) -> 65000

Sheet Гудронатор
A1: Содержание!A1
B3: Н 421 УА 799 | C3: X89503670M0FZ1033 | D3: Специальный Автогудронатор РЕГИОН 45 АС-С41R | E3: 2021
A5: Дата документа | B5: номер документа | C5: поставщик | D5: вид работ | E5: стоимость общая | F5: стоимость запасных частей | G5: стоимость работ
A6: 45718 | B6: 9019876512 | C6: АПР | D6: фильтр топливный | E6: =SUM(F6:G6) -> 736.84 | F6: 736.84
E7: =SUM(F7:G7) -> 0
E8: =SUM(F8:G8) -> 0
E9: =SUM(F9:G9) -> 0
E10: =SUM(F10:G10) -> 0
A11: Итого | E11: =SUM(E6:E10) -> 736.84 | F11: =SUM(F6:F10) -> 736.84 | G11: =SUM(G6:G10) -> 0

Sheet К 487
A1: Содержание!A1
B3: Н 487 АА 977 | C3: XTC652005К1409565(6) | D3: Автосамосвал КАМАЗ К3340 6520-53 | E3: 2019
A5: Дата документа | B5: номер документа | C5: поставщик | D5: вид работ | E5: стоимость общая | F5: стоимость запасных частей | G5: стоимость работ
A6: 46220 | B6: 3296/4 | C6: т-запчасти | D6: стартер | E6: =SUM(F6:G6) -> 25674 | F6: 25674
A7: 46140 | B7: 214 | C7: Тракмастер 42 | D7: замена ЦПГ | E7: =SUM(F7:G7) -> 164323 | F7: 34323 | G7: 130000
E8: =SUM(F8:G8) -> 0
E9: =SUM(F9:G9) -> 0
E10: =SUM(F10:G10) -> 0
A11: Итого | E11: =SUM(E6:E10) -> 189997 | F11: =SUM(F6:F10) -> 59997 | G11: =SUM(G6:G10) -> 130000

Sheet К 877
A1: Содержание!A1
B3: К 877 ТУ 799 | C3: XTC652005L1424014 | D3: Автосамосвал КАМАЗ К3340 6520-53 | E3: 2020
A5: Дата документа | B5: номер документа | C5: поставщик | D5: вид работ | E5: стоимость общая | F5: стоимость запасных частей | G5: стоимость работ
A6: 45748 | B6: 179 | C6: Тракмастер 42 | D6: ремонт топливной системы | E6: =SUM(F6:G6) -> 115993 | F6: 45993 | G6: 70000
A7: 46153 | B7: 240 | C7: Тракмастер 42 | D7: регулировка кулисы | E7: =SUM(F7:G7) -> 9850 | G7: 9850
A8: 46231 | B8: 330 | C8: Тракмастер 42 | D8: ремонт топливной системы | E8: =SUM(F8:G8) -> 70000 | F8: 39000 | G8: 31000
E9: =SUM(F9:G9) -> 0
E10: =SUM(F10:G10) -> 0
E11: =SUM(F11:G11) -> 0
E12: =SUM(F12:G12) -> 0
E13: =SUM(F13:G13) -> 0
E14: =SUM(F14:G14) -> 0
E15: =SUM(F15:G15) -> 0
E16: =SUM(F16:G16) -> 0
A17: Итого | E17: =SUM(E6:E16) -> 195843 | F17: =SUM(F6:F16) -> 84993 | G17: =SUM(G6:G16) -> 110850

Sheet К 927
A1: Содержание!A1
B3: К 927 ТУ 799 | C3: XTC652005L1418059 | D3: Автосамосвал КАМАЗ К3340 6520-53 | E3: 2020
A5: Дата документа | B5: номер документа | C5: поставщик | D5: вид работ | E5: стоимость общая | F5: стоимость запасных частей | G5: стоимость работ
A6: 45698 | B6: 65 | C6: ООО Тракмастер 42 | D6: ремонт топливной системы | E6: =SUM(F6:G6) -> 252628 | F6: 62220 | G6: 190408
A7: 46053 | B7: 349\4 | C7: т-запчасть | D7: корпус воздушного фильтра | E7: =SUM(F7:G7) -> 19860 | F7: 19860
A8: 46056 | B8: 11 | C8: ИП Саргсян | D8: ремонт гидроцилиндра кузова | E8: =SUM(F8:G8) -> 61000 | F8: 61000
A9: 46113 | B9: 140 | C9: Тракмастер 42 | D9: ремонт топливной системы | E9: =SUM(F9:G9) -> 30020 | F9: 13970 | G9: 16050
A10: 46163 | B10: 264 | C10: Тракмастер 42 | D10: ремонт топливной системы | E10: =SUM(F10:G10) -> 128240 | F10: 52000 | G10: 76240
A11: 46183 | B11: 49 | C11: ИП Баранов | D11: ремонт подьема кузова | E11: =SUM(F11:G11) -> 12000 | G11: 12000
A12: 46251 | B12: 170 | C12: ИП Саргсян | D12: ботовая | E12: =SUM(F12:G12) -> 38000 | F12: 38000
E13: =SUM(F13:G13) -> 0
E14: =SUM(F14:G14) -> 0
E15: =SUM(F15:G15) -> 0
E16: =SUM(F16:G16) -> 0
E17: =SUM(F17:G17) -> 0
E18: =SUM(F18:G18) -> 0
E19: =SUM(F19:G19) -> 0
A20: Итого | E20: =SUM(E6:E19) -> 541748 | F20: =SUM(F6:F19) -> 247050 | G20: =SUM(G6:G19) -> 294698

Sheet К 983
A1: Содержание!A1
B3: К 983 ТУ 799 | C3: XTC652005L1424011 | D3: Автосамосвал КАМАЗ К3340 6520-53 | E3: 2020
A5: Дата документа | B5: номер документа | C5: поставщик | D5: вид работ | E5: стоимость общая | F5: стоимость запасных частей | G5: стоимость работ
A6: 45699 | B6: 32 | C6: ООО Тракмастер 42 | D6: ремонт топливной системы | E6: =SUM(F6:G6) -> 203926 | F6: 157366 | G6: 46560
A7: 45691 | B7: 45 | C7: ООО Тракмастер 42 | D7: Прошивка ЭБУ | E7: =SUM(F7:G7) -> 15000 | G7: 15000
A8: 46235 | B8: 3374/4 | C8: Т-запчасти | D8: барабан тормозной | E8: =SUM(F8:G8) -> 36854 | F8: 36854
A9: 46235 | B9: 3372-4 | C9: Т-запчасти | D9: стартер | E9: =SUM(F9:G9) -> 24571 | F9: 24571
A10: 46255 | B10: 3627/4 | C10: Т-запчасти | D10: шланг, антифриз | E10: =SUM(F10:G10) -> 8172 | F10: 8172
A11: 46121 | B11: 59 | C11: ИП Саргсян | D11: кап ремонт двс | E11: =SUM(F11:G11) -> 1089500 | G11: 1089500
A12: 46223 | B12: 691 | C12: Атлант | D12: шины | E12: =SUM(F12:G12) -> 135960 | F12: 135960
A13: 46251 | B13: 170 | C13: ИП Саргсян | D13: ремонт ЭБУ | E13: =SUM(F13:G13) -> 35000 | G13: 35000
E14: =SUM(F14:G14) -> 0
E15: =SUM(F15:G15) -> 0
E16: =SUM(F16:G16) -> 0
E17: =SUM(F17:G17) -> 0
E18: =SUM(F18:G18) -> 0
E19: =SUM(F19:G19) -> 0
E20: =SUM(F20:G20) -> 0
A21: Итого | E21: =SUM(E6:E20) -> 1548983 | F21: =SUM(F6:F20) -> 362923 | G21: =SUM(G6:G20) -> 1186060

Sheet К 994
A1: Содержание!A1
B3: К 994 ТУ 799 | C3: XTC652005L1423865 | D3: Автосамосвал КАМАЗ К3340 6520-53 | E3: 2020
A5: Дата документа | B5: номер документа | C5: поставщик | D5: вид работ | E5: стоимость общая | F5: стоимость запасных частей | G5: стоимость работ
A6: 45761 | B6: 221 | C6: Тракмастер 42 | D6: ремонт топливной системы | E6: =SUM(F6:G6) -> 117015 | F6: 28215 | G6: 88800
A7: 45798 | B7: 294 | C7: Тракмастер 42 | D7: регулировка клапанов | E7: =SUM(F7:G7) -> 20500 | F7: 20500
A8: 46034 | B8: 74/2 | C8: Т-Запчасть | D8: стартер | E8: =SUM(F8:G8) -> 20892 | F8: 20892
A9: 46037 | B9: 266 | C9: Т-Запчасть | D9: блок фара | E9: =SUM(F9:F9) -> 10832 | F9: 10832
A10: 46077 | B10: 750\4 | C10: Т-Запчасть | D10: Насос ГУРа | E10: =SUM(F10:F10) -> 21691 | F10: 21691
A11: 46235 | B11: 3372/4 | C11: Т-Запчасть | D11: редуктор привода ТНВД | E11: =SUM(F11:F11) -> 76890 | F11: 76890
A12: 46127 | B12: 194 | C12: Тракмастер 42 | D12: замена датчика | E12: =SUM(F12:F12) -> 0 | G12: 13000
A13: 46163 | B13: 34 | C13: ИП Баранов | D13: ремонт проводки | E13: =SUM(F13:F13) -> 0 | G13: 20000
E14: =SUM(F14:F14) -> 0
E15: =SUM(F15:F15) -> 0
E16: =SUM(F16:F16) -> 0
E17: =SUM(F17:F17) -> 0
E18: =SUM(F18:F18) -> 0
E19: =SUM(F19:F19) -> 0
E20: =SUM(F20:G20) -> 0
A21: Итого | E21: =SUM(E6:E20) -> 267820 | F21: =SUM(F6:F20) -> 179020 | G21: =SUM(G6:G20) -> 121800

Sheet SH 152
A1: Содержание!A1
B3: Х 152 НО 799 | C3: LZGJRDR47HX063924 | D3: Самосвал SHACMAN SX3256DR384 | E3: 2017
A5: Дата документа | B5: номер документа | C5: поставщик | D5: вид работ | E5: стоимость общая | F5: стоимость запасных частей | G5: стоимость работ
A6: 45692 | B6: 2420 | C6: ООО ФриВэй | D6: запчасти | E6: =SUM(F6:G6) -> 17005 | F6: 17005
A7: 45992 | C7: грузовой доктор | D7: покраска | E7: 270000 | G7: 270000
A8: 46232 | B8: УТ-35521 | C8: ФриВэй | D8: Радиатор кондиционера | E8: =SUM(F8:G8) -> 6746 | F8: 6746
A9: 46169 | B9: 40 | C9: ИП Баранов | D9: ремонт электрики | E9: =SUM(F9:G9) -> 8000 | G9: 8000
E10: =SUM(F10:G10) -> 0
E11: =SUM(F11:G11) -> 0
E12: =SUM(F12:G12) -> 0
E13: =SUM(F13:G13) -> 0
E14: =SUM(F14:G14) -> 0
E15: =SUM(F15:G15) -> 0
E16: =SUM(F16:G16) -> 0
E17: =SUM(F17:G17) -> 0
A18: Итого | E18: =SUM(E6:E17) -> 301751 | F18: =SUM(F6:F17) -> 23751 | G18: =SUM(G6:G17) -> 278000

Sheet SH 265
A1: Содержание!A1
B3: Х 265 НО 799 | C3: LZGJRDR42HX063927 | D3: Самосвал SHACMAN SX3256DR384 | E3: 2017
A5: Дата документа | B5: номер документа | C5: поставщик | D5: вид работ | E5: стоимость общая | F5: стоимость запасных частей | G5: стоимость работ
A6: 46051 | B6: УТ-3301 | C6: Фривей | D6: дверь правая и з\ч | E6: =SUM(F6:G6) -> 52578 | F6: 52578
A7: 46058 | B7: 94 | C7: СД МСК | D7: дверь левая | E7: =SUM(F7:G7) -> 32900 | F7: 32900
A8: 46077 | B8: 750\4 | C8: Т-Запчасть | D8: стремянки кузова | E8: =SUM(F8:G8) -> 5150 | F8: 5150
E9: =SUM(F9:G9) -> 0
E10: =SUM(F10:G10) -> 0
A11: Итого | E11: =SUM(E6:E10) -> 90628 | F11: =SUM(F6:F10) -> 90628 | G11: =SUM(G6:G10) -> 0

Sheet SH 287
A1: Содержание!A1
B3: Х 287 НО 799 | C3: LZGJRDR45HX063923 | D3: Самосвал SHACMAN SX3256DR384 | E3: 2017
A5: Дата документа | B5: номер документа | C5: поставщик | D5: вид работ | E5: стоимость общая | F5: стоимость запасных частей | G5: стоимость работ
A6: 46057 | B6: 57 | C6: ТракМастер 42 | D6: ремонт форсунок | E6: =SUM(F6:G6) -> 100460 | F6: 49920 | G6: 50540
A7: 46232 | B7: УТ-35629 | C7: Фривэй | D7: венец маховика | E7: =SUM(F7:G7) -> 6292 | F7: 6292
A8: 46264 | B8: 3728\4 | C8: Т-запчасти | D8: головка блока цилиндров, форсунки | E8: =SUM(F8:G8) -> 73545 | F8: 73545
A9: 46169 | B9: 40 | C9: ИП Баранов | D9: ремонт электрики | E9: =SUM(F9:G9) -> 10000 | G9: 10000
A10: 46202 | B10: 296 | C10: ТракМастер 42 | D10: диагностика и ремонт | E10: =SUM(F10:G10) -> 5000 | G10: 5000
E11: =SUM(F11:G11) -> 0
E12: =SUM(F12:G12) -> 0
E13: =SUM(F13:G13) -> 0
E14: =SUM(F14:G14) -> 0
E15: =SUM(F15:G15) -> 0
E16: =SUM(F16:G16) -> 0
A17: Итого | E17: =SUM(E6:E16) -> 195297 | F17: =SUM(F6:F16) -> 129757 | G17: =SUM(G6:G16) -> 65540

Sheet К 320
A1: Содержание!A1
B3: 320 | D3: Самосвал Камаз 6520 | E3: 2020
A5: Дата документа | B5: номер документа | C5: поставщик | D5: вид работ | E5: стоимость общая | F5: стоимость запасных частей | G5: стоимость работ
A6: 46048 | B6: 40 | C6: Тракмастер 42 | D6: ремонт топливной системы | E6: =SUM(F6:G6) -> 100280 | F6: 41340 | G6: 58940
A7: 46113 | B7: 145 | C7: Тракмастер 42 | D7: ремонт топливной системы | E7: =SUM(F7:G7) -> 88381 | F7: 13631 | G7: 74750
E8: =SUM(F8:G8) -> 0
E9: =SUM(F9:G9) -> 0
E10: =SUM(F10:G10) -> 0
A11: Итого | E11: =SUM(E6:E10) -> 188661 | F11: =SUM(F6:F10) -> 54971 | G11: =SUM(G6:G10) -> 133690

Sheet SH 989
A1: Содержание!A1
B3: О 989 РЕ 799 | C3: LZGJLDR41CX062486 | D3: Самосвал SHACMAN SX3255DR384 | E3: 2012
A5: Дата документа | B5: номер документа | C5: поставщик | D5: вид работ | E5: стоимость общая | F5: стоимость запасных частей | G5: стоимость работ
E6: =SUM(F6:G6) -> 0
E7: =SUM(F7:G7) -> 0
E8: =SUM(F8:G8) -> 0
E9: =SUM(F9:G9) -> 0
E10: =SUM(F10:G10) -> 0
A11: Итого | E11: =SUM(E6:E10) -> 0 | F11: =SUM(F6:F10) -> 0 | G11: =SUM(G6:G10) -> 0

Sheet Sitrak
A1: Содержание!A1
B3: H 478 BO 977 | C3: LZZ7CCWDXPC609266 | D3: Sitrak C7H ZZ4186V361HE | E3: 2023
A5: Дата документа | B5: номер документа | C5: поставщик | D5: вид работ | E5: стоимость общая | F5: стоимость запасных частей | G5: стоимость работ
A8: 46062 | B8: УТ-152 | C8: МТМ Логистик | D8: расходники для ТО | E8: =SUM(F8:G8) -> 23350 | F8: 23350
A9: 46255 | B9: ДВС00001942 | C9: Технический центр ДВС | D9: дефектовка ГБЦ | E9: =SUM(F9:G9) -> 33340 | G9: 33340
A10: 46258 | B10: УТ-40813 | C10: Фри Вэй | D10: форсунки двигателя | E10: =SUM(F10:G10) -> 132000 | F10: 132000
A11: 46252 | B11: УТ-953 | C11: МТМ Логистик | D11: ГБЦ | E11: =SUM(F11:G11) -> 288800 | F11: 288800
A12: 46135 | B12: 1181 | C12: СиноРус Сервис | D12: ремонт эл.проводки | E12: =SUM(F12:G12) -> 22490 | G12: 22490
A13: 46156 | B13: 1378 | C13: СиноРус Сервис | D13: замена педали газа | E13: =SUM(F13:G13) -> 11810 | F13: 5650 | G13: 6160
A14: 46141 | B14: УТ-716 | C14: МТМ Логистик | D14: колодки, ключ | E14: =SUM(F14:G14) -> 11400 | F14: 11400
A15: 46209 | B15: 1916 | C15: СиноРус Сервис | D15: ремонт жгута проводки | E15: =SUM(F15:G15) -> 14060 | G15: 14060
A16: 46241 | B16: 903 | C16: МТМ Логистик | D16: Турбина | E16: =SUM(F16:G16) -> 62900 | F16: 62900
A17: 46252 | B17: 953 | C17: МТМ Логистик | D17: ГБЦ | E17: =SUM(F17:G17) -> 288800 | F17: 288800
A18: 46255 | B18: 970 | C18: МТМ Логистик | D18: Комплект болтов ГБЦ | E18: =SUM(F18:G18) -> 29600 | F18: 29600
A19: 46265 | B19: 379 | C19: Тракмастер-42 | D19: работы по уствновке ГБЦ | E19: =SUM(F19:G19) -> 60000 | G19: 60000
E20: =SUM(F20:G20) -> 0
E21: =SUM(F21:G21) -> 0
E22: =SUM(F22:G22) -> 0
E23: =SUM(F23:G23) -> 0
A24: Итого | E24: =SUM(E6:E23) -> 978550 | F24: =SUM(F6:F23) -> 842500 | G24: =SUM(G6:G23) -> 136050

Sheet Scania
A1: Содержание!A1
B3: М 949 ХУ 799 | C3: 9BSP6X40003888559 | D3: SCANIA Р400 СА6Х4НSZ Грузовой тягач седельный | E3: 2016
A5: Дата документа | B5: номер документа | C5: поставщик | D5: вид работ | E5: стоимость общая | F5: стоимость запасных частей | G5: стоимость работ
A6: 45992 | C6: грузовой доктор | D6: покраска | E6: =SUM(F6:G6) -> 345000 | G6: 345000
A7: 46119 | B7: УТ-539 | C7: МТМ Логистик | D7: РМК рессоры | E7: =SUM(F7:G7) -> 48200 | F7: 48200
A8: 46120 | B8: УТ-262 | C8: МТМ Логистик | D8: палец рессоры | E8: =SUM(F8:G8) -> 2200 | F8: 2200
A9: 46163 | B9: УТ-847 | C9: МТМ Логистик | D9: крестовина | E9: =SUM(F9:G9) -> 12000 | F9: 12000
A10: 46169 | B10: 40 | C10: ИП Баранов | D10: ремонт электрики | E10: =SUM(F10:G10) -> 10000 | G10: 10000
A11: 46210 | B11: 2644 | C11: Атлас | D11: диски | E11: =SUM(F11:G11) -> 12560 | F11: 12560
A12: 46213 | B12: 2713 | C12: Атлас | D12: шины перед | E12: =SUM(F12:G12) -> 53960 | F12: 53960
A13: 46218 | B13: 3988 | C13: СканЮго Восток | D13: ремонт платы ЭБУ | E13: =SUM(F13:G13) -> 72952 | G13: 72952
A14: 46231 | B14: 331 | C14: Тракмастер 42 | D14: ремонт шкворней | E14: =SUM(F14:G14) -> 46920 | F14: 820 | G14: 46100
A15: 46238 | B15: 862 | C15: спутник | D15: сход развал | E15: =SUM(F15:G15) -> 15582 | G15: 15582
A16: 46220 | B16: 1399 | C16: МТМ Логистик | D16: РК амортизатора | E16: =SUM(F16:G16) -> 8080 | F16: 8080
A17: 46237 | B17: 876 | C17: МТМ Логистик | D17: тяга рулевая | E17: =SUM(F17:G17) -> 8400 | F17: 8400
A18: 46229 | B18: 1414 | C18: МТМ Логистик | D18: РК пальца рессоры, серьга рессоры | E18: =SUM(F18:G18) -> 7500 | F18: 7500
E19: =SUM(F19:G19) -> 0
E20: =SUM(F20:G20) -> 0
A21: Итого | E21: =SUM(E6:E20) -> 643354 | F21: =SUM(F6:F20) -> 153720 | G21: =SUM(G6:G20) -> 489634

Sheet Specpricep
A1: Содержание!A1
B3: ЕО 7112 77 | C3: Х89994273М0ВА2539 | D3: Specpricep 9942L3 специализированный полуприцеп тяжеловоз | E3: 2021
A5: Дата документа | B5: номер документа | C5: поставщик | D5: вид работ | E5: стоимость общая | F5: стоимость запасных частей | G5: стоимость работ
A6: 46060 | B6: УТ-148 | C6: МТМ Логистик | D6: болт, гайка рессоры | E6: =SUM(F6:G6) -> 2000 | F6: 2000
A7: 46108 | B7: 132 | C7: Стропсервис | D7: цепи для крепления техники | E7: =SUM(F7:G7) -> 20200 | F7: 20200
A8: 46112 | B8: УТ-230 | C8: МТМ Логистик | D8: РМК тормозной системы | E8: =SUM(F8:G8) -> 80100 | F8: 80100
A9: 46129 | B9: УТ-625 | C9: МТМ Логистик | D9: рессора пневматическая | E9: =SUM(F9:G9) -> 6500 | F9: 6500
A10: 46213 | B10: 3076 | C10: ООО ЗКМ | D10: насос аппарели | E10: =SUM(F10:G10) -> 6200 | F10: 6200
A11: 46216 | B11: 1339 | C11: МТМ Логистик | D11: рессора пневматическая | E11: =SUM(F11:G11) -> 9450 | F11: 9450
A12: 46248 | B12: 606271 | C12: ИП Мелкин | D12: восстановление чулка | E12: =SUM(F12:G12) -> 44265 | G12: 44265
E13: =SUM(F13:G13) -> 0
E14: =SUM(F14:G14) -> 0
E15: =SUM(F15:G15) -> 0
E16: =SUM(F16:G16) -> 0
A17: Итого | E17: =SUM(E6:E16) -> 168715 | F17: =SUM(F6:F16) -> 124450 | G17: =SUM(G6:G16) -> 44265

Sheet Sinanli
A1: Содержание!A1
B3: ХХ 0555 77 | C3: NP9ST4FLFP0225021 | D3: ПРИЦЕП Sinanli Tanker ST4FLF | E3: 2023
A5: Дата документа | B5: номер документа | C5: поставщик | D5: вид работ | E5: стоимость общая | F5: стоимость запасных частей | G5: стоимость работ
A6: 46118 | B6: 156 | C6: ТракМастер 42 | D6: ремонт тормозной системы | E6: =SUM(F6:G6) -> 141574 | F6: 8774 | G6: 132800
A7: 46195 | B7: 526 | C7: Атлант | D7: шины | E7: =SUM(F7:G7) -> 71520 | F7: 71520
A8: 46204 | B8: 67 | C8: ИП Баранов | D8: ремонт проводки | E8: =SUM(F8:G8) -> 16000 | G8: 16000
A9: 46224 | B9: 6 | C9: СНТ Трейд | D9: ступичные гайки | E9: =SUM(F9:G9) -> 14139.72 | F9: 14139.72
E10: =SUM(F10:G10) -> 0
E11: =SUM(F11:G11) -> 0
E12: =SUM(F12:G12) -> 0
E13: =SUM(F13:G13) -> 0
E14: =SUM(F14:G14) -> 0
E15: =SUM(F15:G15) -> 0
E16: =SUM(F16:G16) -> 0
E17: =SUM(F17:G17) -> 0
A18: Итого | E18: =SUM(E6:E17) -> 243233.72 | F18: =SUM(F6:F17) -> 94433.72 | G18: =SUM(G6:G17) -> 148800

Sheet Ensign 8102
A1: Содержание!A1
B3: 77 МН 8102 | C3: 567006LDPNB279771 | D3: Погрузчик фронтальный ENSIGN YX635 | E3: 2022
A5: Дата документа | B5: номер документа | C5: поставщик | D5: вид работ | E5: стоимость общая | F5: стоимость запасных частей | G5: стоимость работ
A6: 46051 | B6: 458 | C6: Дорсервис | D6: НОЖ ковша | E6: =SUM(F6:G6) -> 23100 | F6: 23100
A7: 46203 | B7: 29 | C7: ООО ТЛ | D7: сочлинение | E7: =SUM(F7:G7) -> 38100 | F7: 38100
E8: =SUM(F8:G8) -> 0
E9: =SUM(F9:G9) -> 0
E10: =SUM(F10:G10) -> 0
A11: Итого | E11: =SUM(E6:E10) -> 61200 | F11: =SUM(F6:F10) -> 61200 | G11: =SUM(G6:G10) -> 0

Sheet Ensign 8101
A1: Содержание!A1
B3: 77 МН 8101 | C3: 567006LDVNB279761 | D3: Погрузчик фронтальный ENSIGN YX635 | E3: 2022
A5: Дата документа | B5: номер документа | C5: поставщик | D5: вид работ | E5: стоимость общая | F5: стоимость запасных частей | G5: стоимость работ
A6: 46051 | B6: 458 | C6: Дорсервис | D6: НОЖ ковша | E6: =SUM(F6:G6) -> 23100 | F6: 23100
E7: =SUM(F7:G7) -> 0
E8: =SUM(F8:G8) -> 0
E9: =SUM(F9:G9) -> 0
E10: =SUM(F10:G10) -> 0
A11: Итого | E11: =SUM(E6:E10) -> 23100 | F11: =SUM(F6:F10) -> 23100 | G11: =SUM(G6:G10) -> 0

Sheet XCMG
A1: Содержание!A1
B3: 77 MM 7009 | C3: XUG0300KVNCB20676 | D3: Фронтальный погручик XCMG ZL3OGV XCMG | E3: 2022
A5: Дата документа | B5: номер документа | C5: поставщик | D5: вид работ | E5: стоимость общая | F5: стоимость запасных частей | G5: стоимость работ
A6: 45699 | B6: ПК196 | C6: ООО ПК-СТ | D6: Вилы палетные | E6: =SUM(F6:G6) -> 160000 | F6: 160000
A7: 46056 | B7: 210 | C7: спецтрейд | D7: шины передние | E7: =SUM(F7:G7) -> 77400 | F7: 77400
A8: 46072 | B8: 288 | C8: спецтрейд | D8: шины задние | E8: =SUM(F8:G8) -> 77400 | F8: 77400
A9: 46050 | B9: 65 | C9: ИП Лысенко | D9: ремонт электрики | E9: =SUM(F9:G9) -> 13000 | G9: 13000
A10: 46051 | B10: 458 | C10: Дорсервис | D10: НОЖ ковша | E10: =SUM(F10:G10) -> 26500 | F10: 26500
E12: =SUM(F12:G12) -> 0
E13: =SUM(F13:G13) -> 0
A14: Итого | E14: =SUM(E6:E13) -> 354300 | F14: =SUM(F6:F13) -> 341300 | G14: =SUM(G6:G13) -> 13000

Sheet Case 4294
A1: Содержание!A1
B3: 77 РЕ 4294 | C3: JAFSR220PJM450990 | D3: Погрузчик фронтальный CASE SR220 | E3: 2018
A5: Дата документа | B5: номер документа | C5: поставщик | D5: вид работ | E5: стоимость общая | F5: стоимость запасных частей | G5: стоимость работ
A6: 45524 | B6: 35642 | C6: ООО Актио Рус | D6: кап ремонт двигателя | E6: =SUM(F6:G6) -> 910683.6 | F6: 910683.6
A7: 45709 | B7: 8525 | C7: ООО Актио Рус | D7: Ремонт ТНВД и форсунок | E7: =SUM(F7:G7) -> 108000 | F7: 108000
A8: 45747 | B8: 14502 | C8: ООО Актио Рус | D8: ручка двери с замком | E8: =SUM(F8:G8) -> 10993.8 | F8: 10993.8
A9: 46104 | B9: 14452 | C9: Актио Рус | D9: болт ковша | E9: =SUM(F9:G9) -> 2244 | F9: 2244
A10: 46146 | B10: В1406 | C10: Вольтаж | D10: ремонт стартера | E10: =SUM(F10:G10) -> 5500 | G10: 5500
A11: 46156 | B11: 24885 | C11: Актио Рус | D11: Венец маховика | E11: =SUM(F11:G11) -> 18556.2 | F11: 18556.2
A12: 46160 | B12: 25681 | C12: Актио Рус | D12: колеса в сборе | E12: =SUM(F12:G12) -> 150401.6 | F12: 150401.6
A13: 46155 | B13: 2190 | C13: Вольтаж | D13: ремонт стартера | E13: =SUM(F13:G13) -> 5500 | G13: 5500
E14: =SUM(F14:G14) -> 0
A15: Итого | E15: =SUM(E6:E14) -> 1211879.2 | F15: =SUM(F6:F14) -> 1200879.2 | G15: =SUM(G6:G14) -> 11000

Sheet Case 7010
A1: Содержание!A1
B3: 77 ММ 7010 | C3: JAFSR200LNM413973 | D3: Колесный мини-погрузчик CASE SR200B | E3: 2022
A5: Дата документа | B5: номер документа | C5: поставщик | D5: вид работ | E5: стоимость общая | F5: стоимость запасных частей | G5: стоимость работ
A6: 46092 | B6: 2301421 | C6: ИП Воробьев | D6: шины 2 шт | E6: =SUM(F6:G6) -> 52000 | F6: 52000
A7: 46147 | B7: 23270 | C7: Актио Рус | D7: накидные гусеницы | E7: =SUM(F7:G7) -> 275236.88 | F7: 275236.88
A8: 46183 | B8: 30947 | C8: Актио Рус | D8: шины,корпус | E8: =SUM(F8:G8) -> 99494.66 | F8: 99494.66
E9: =SUM(F9:G9) -> 0
E10: =SUM(F10:G10) -> 0
E11: =SUM(F11:G11) -> 0
E12: =SUM(F12:G12) -> 0
E13: =SUM(F13:G13) -> 0
E14: =SUM(F14:G14) -> 0
E15: =SUM(F15:G15) -> 0
E16: =SUM(F16:G16) -> 0
E17: =SUM(F17:G17) -> 0
E18: =SUM(F18:G18) -> 0
E19: =SUM(F19:G19) -> 0
A20: Итого | E20: =SUM(E6:E19) -> 426731.54 | F20: =SUM(F6:F19) -> 426731.54 | G20: =SUM(G6:G19) -> 0

Sheet Case 580
A1: Содержание!A1
B3: 77 РЕ 4293 | C3: FNH0580TNJHH01925 | D3: Экскаватор погрузчик Case 580Т | E3: 2017
A5: Дата документа | B5: номер документа | C5: поставщик | D5: вид работ | E5: стоимость общая | F5: стоимость запасных частей | G5: стоимость работ
A6: 45687 | B6: 45 | C6: ИП Лысенко | D6: Ремонт печки салона | E6: =SUM(F6:G6) -> 18000 | G6: 18000
A7: 45677 | B7: 125 | C7: ООО МСБ Групп | D7: Замена стекол | E7: =SUM(F7:G7) -> 23700 | F7: 14800 | G7: 8900
A8: 46084 | B8: 10992 | C8: АктиоРус | D8: рулевые тяги | E8: =SUM(F8:G8) -> 24495 | F8: 24495
A9: 46123 | B9: 19064 | C9: АктиоРус | D9: педаль кнопка молота | E9: =SUM(F9:G9) -> 37000.16 | F9: 37000.16
A10: 46128 | B10: 19874 | C10: АктиоРус | D10: Задний фонарь | E10: =SUM(F10:G10) -> 3345 | F10: 3345
A11: 46147 | B11: 23448 | C11: АктиоРус | D11: Прокладка крышки клапанов | E11: =SUM(F11:G11) -> 2220 | F11: 2220
A12: 46147 | B12: ТИ-31742 | C12: Технопарк | D12: РК гидромолота | E12: =SUM(F12:G12) -> 7128 | F12: 7128
A13: 46225 | B13: 39102 | C13: АктиоРус | D13: пальцы стрелы | E13: =SUM(F13:G13) -> 6143.31 | F13: 6143.31
A14: 46238 | B14: 84 | C14: ИП Баранов | D14: работа с проводкой | E14: =SUM(F14:G14) -> 18000 | G14: 18000
A15: 46254 | B15: 44894 | C15: АктиоРус | D15: сальник бортовой | E15: =SUM(F15:G15) -> 5820 | F15: 5820
A16: 46218 | B16: 37700 | C16: АктиоРус | D16: ручка КПП | E16: =SUM(F16:G16) -> 10984.88 | F16: 10984.88
E17: =SUM(F17:G17) -> 0
E18: =SUM(F18:G18) -> 0
E19: =SUM(F19:G19) -> 0
E20: =SUM(F20:G20) -> 0
E21: =SUM(F21:G21) -> 0
A22: Итого | E22: =SUM(E6:E21) -> 156836.35 | F22: =SUM(F6:F21) -> 111936.35 | G22: =SUM(G6:G21) -> 44900

Sheet Case 570
A1: Содержание!A1
D3: Экскаватор погрузчик Case 570SТ | E3: 2017
A5: Дата документа | B5: номер документа | C5: поставщик | D5: вид работ | E5: стоимость общая | F5: стоимость запасных частей | G5: стоимость работ
A6: 45707 | B6: 3650 | C6: ООО Мех.завод Конструктив | D6: восстановление рукояти | E6: =SUM(F6:G6) -> 40000 | G6: 40000
A7: 45707 | B7: 8052 | C7: ООО Актио РУС | D7: салазки для рукояти | E7: =SUM(F7:G7) -> 5817.6 | F7: 5817.6
A8: 45720 | B8: ФР-ГЦ-1-0000277 | C8: ООО Гидравлик Групп | D8: ремонт гидроцилиндра | E8: =SUM(F8:G8) -> 111900 | G8: 111900
A9: 45735 | B9: 12776 | C9: ООО Актио РУС | D9: датчик уровня топлива | E9: =SUM(F9:G9) -> 4164 | F9: 4164
A10: 45992 | C10: грузовой доктор | D10: покраска | E10: =SUM(F10:G10) -> 200000 | G10: 200000
A11: 46050 | B11: 6 | C11: ИП Асаян А.Р. | D11: ремонт радиатора | E11: =SUM(F11:G11) -> 27000 | G11: 27000
A12: 46079 | B12: 9703 | C12: ООО Актио РУС | D12: Кулаки поворотные и тяги рулевые | E12: =SUM(F12:G12) -> 182000 | F12: 182000
A13: 46086 | B13: 11574 | C13: ООО Актио РУС | D13: палец стрелы | E13: =SUM(F13:G13) -> 3480 | F13: 3480
A14: 46104 | B14: 14958 | C14: Актио Рус | D14: замена кулаков | E14: =SUM(F14:G14) -> 58344 | G14: 58344
A15: 46104 | B15: 14957 | C15: Актио Рус | D15: сальники, втулки редуктора | E15: =SUM(F15:G15) -> 25773 | F15: 25773
A16: 46111 | B16: 16442 | C16: Актио Рус | D16: сальники, | E16: =SUM(F16:G16) -> 8525 | F16: 8525
A17: 46147 | B17: ТИ-31742 | C17: Технопарк | D17: РМК гидромолота | E17: =SUM(F17:G17) -> 7178 | F17: 7178
A18: 46182 | B18: 30813 | C18: Актио Рус | D18: фильтр и шины | E18: =SUM(F18:G18) -> 73243 | F18: 73243
A19: 46197 | B19: 33583 | C19: Актио Рус | D19: тормозные цилиндры и жидкость | E19: =SUM(F19:G19) -> 25500 | F19: 25500
A20: 46203 | B20: 2037 | C20: МСБ Групп | D20: стекло заднее | E20: =SUM(F20:G20) -> 19950 | F20: 8450 | G20: 11500
A21: 46242 | B21: 42608 | C21: Актио Рус | D21: генератор | E21: =SUM(F21:G21) -> 32499.58 | F21: 32499.58
E22: =SUM(F22:G22) -> 0
E23: =SUM(F23:G23) -> 0
E24: =SUM(F24:G24) -> 0
E25: =SUM(F25:G25) -> 0
E26: =SUM(F26:G26) -> 0
E27: =SUM(F27:G27) -> 0
A28: Итого | E28: =SUM(E6:E27) -> 825374.18 | F28: =SUM(F6:F27) -> 376630.18 | G28: =SUM(G6:G27) -> 448744

Sheet CAT 428
A1: Содержание!A1
B3: 77 ММ 7056 | C3: CAT00428CL7D00383 | D3: Экскаватор-погрузчик Caterpillar 428 | E3: 2020
A5: Дата документа | B5: номер документа | C5: поставщик | D5: вид работ | E5: стоимость общая | F5: стоимость запасных частей | G5: стоимость работ
A6: 45726 | B6: 457296809 | C6: АПР | D6: палец челюсти | E6: =SUM(F6:G6) -> 4771.18 | F6: 4771.18
A7: 45726 | B7: 100325-6062 | C7: Ф.А. Авто | D7: АКБ | E7: =SUM(F7:G7) -> 16655.6 | F7: 16655.6
A8: 46051 | B8: 11 | C8: ИП Топал | D8: РМК аутригеров | E8: =SUM(F8:G8) -> 14000 | F8: 14000
A9: 46114 | B9: 40 | C9: ИП Топал | D9: замена стабилизатора аутригеров | E9: =SUM(F9:G9) -> 12000 | G9: 12000
A10: 46147 | B10: ТИ-31535 | C10: Технопарк | D10: Гидромолот и квик каплер | E10: =SUM(F10:G10) -> 293716 | F10: 293716
E11: =SUM(F11:G11) -> 0
E12: =SUM(F12:G12) -> 0
E13: =SUM(F13:G13) -> 0
A14: Итого | E14: =SUM(E6:E13) -> 341142.78 | F14: =SUM(F6:F13) -> 329142.78 | G14: =SUM(G6:G13) -> 12000

Sheet CAT 432
A1: Содержание!A1
B3: 77 РВ 6800 | C3: САТ0432FVLYJ00794 | D3: Экскаватор-погрузчик Caterpillar 432F2 | E3: 2018
A5: Дата документа | B5: номер документа | C5: поставщик | D5: вид работ | E5: стоимость общая | F5: стоимость запасных частей | G5: стоимость работ
A6: 45677 | B6: 11 | C6: ООО ММС | D6: запчасти | E6: =SUM(F6:G6) -> 14340 | F6: 14340
A7: 45728 | B7: ФР-ММ-0005213 | C7: Гидравлик Групп | D7: ремонт гидр. рукава | E7: =SUM(F7:G7) -> 12798.7 | F7: 12798.7
A8: 46129 | B8: ТИ-27878 | C8: Технопарк | D8: пика для отбойнтка | E8: =SUM(F8:G8) -> 10573 | F8: 10573
A9: 46139 | B9: 203 | C9: е-зап | D9: радиатор кондиционера | E9: =SUM(F9:G9) -> 23133 | G9: 23133
A10: 46148 | B10: 93 | C10: Тепло холод | D10: запрака кондиционера | E10: =SUM(F10:G10) -> 13500 | G10: 13500
A11: 46156 | B11: 24892 | C11: АктиоРус | D11: сальник полуоси | E11: =SUM(F11:G11) -> 1864 | F11: 1864
A12: 46162 | B12: 2650 | C12: АктиоРус | D12: вилы с установкой | E12: =SUM(F12:G12) -> 127560.14 | F12: 98560.14 | G12: 29000
A13: 46258 | B13: 54230 | C13: Технопарк | D13: пиеа | E13: =SUM(F13:G13) -> 11120 | F13: 11120
E14: =SUM(F14:G14) -> 0
A15: Итого | E15: =SUM(E6:E14) -> 214888.84 | F15: =SUM(F6:F14) -> 149255.84 | G15: =SUM(G6:G14) -> 65633

Sheet МТЗ 82
A1: Содержание!A1
B3: 77 РМ 6819 | C3: 404(Y4R900Z01L1102335) | D3: МУП-351.ТСТ машина для коммунального хозяйства | E3: 2020
A5: Дата документа | B5: номер документа | C5: поставщик | D5: вид работ | E5: стоимость общая | F5: стоимость запасных частей | G5: стоимость работ
A6: 46268 | B6: 3804\4 | C6: Т-запчасти | D6: к-т сцепления | E6: =SUM(F6:G6) -> 29436 | F6: 29436
E7: =SUM(F7:G7) -> 0
E8: =SUM(F8:G8) -> 0
E9: =SUM(F9:G9) -> 0
E10: =SUM(F10:G10) -> 0
A11: Итого | E11: =SUM(E6:E10) -> 29436 | F11: =SUM(F6:F10) -> 29436 | G11: =SUM(G6:G10) -> 0

Sheet Sanny 55
A1: Содержание!A1
B3: 77 РМ 6996 | C3: SY0058CC38558/OF5110063N4L70066CK | D3: Гусеничный экскаватор SANY,SY55C | E3: 2022
A5: Дата документа | B5: номер документа | C5: поставщик | D5: вид работ | E5: стоимость общая | F5: стоимость запасных частей | G5: стоимость работ
A6: 45691 | B6: ААМС-0000903 | C6: ООО АСТ | D6: запчасти | E6: =SUM(F6:G6) -> 4721.98 | F6: 4721.98
A7: 45691 | B7: 99 | C7: ООО ГТ Групп | D7: запчасти | E7: =SUM(F7:G7) -> 760 | F7: 760
A8: 45691 | B8: М-232 | C8: ООО Мирапартс | D8: запчасти | E8: =SUM(F8:G8) -> 13660 | F8: 13660
E9: =SUM(F9:G9) -> 0
E10: =SUM(F10:G10) -> 0
E11: =SUM(F11:G11) -> 0
E12: =SUM(F12:G12) -> 0
A13: Итого | E13: =SUM(E6:E12) -> 19141.98 | F13: =SUM(F6:F12) -> 19141.98 | G13: =SUM(G6:G12) -> 0

Sheet Sanny 75
A1: Содержание!A1
B3: 77 МН 8147 | C3: SY0079CC30958/0F5110070N4 | D3: Гусеничный экскаватор SANYSY75C
A5: Дата документа | B5: номер документа | C5: поставщик | D5: вид работ | E5: стоимость общая | F5: стоимость запасных частей | G5: стоимость работ
A6: 45678 | B6: М-104 | C6: ООО Мирапартс | D6: запчасти | E6: =SUM(F6:G6) -> 11800 | F6: 11800
A7: 45497 | B7: ААМС-0005578 | C7: ООО АСТ | D7: запчасти | E7: =SUM(F7:G7) -> 15903.1 | F7: 15903.1
A8: 46128 | B8: ААМС-0003392 | C8: ООО АСТ | D8: катридж воздушного фильтра | E8: =SUM(F8:G8) -> 9009.98 | F8: 9009.98
A9: 46184 | B9: 5016 | C9: ООО АСТ | D9: стекло крыши изогнутое | E9: =SUM(F9:G9) -> 5098 | F9: 5098
A10: 46211 | B10: 2123 | C10: МСБ Групп | D10: вклейка стекла | E10: =SUM(F10:G10) -> 12000 | G10: 12000
E11: =SUM(F11:G11) -> 0
E12: =SUM(F12:G12) -> 0
E13: =SUM(F13:G13) -> 0
E14: =SUM(F14:G14) -> 0
E15: =SUM(F15:G15) -> 0
E16: =SUM(F16:G16) -> 0
A17: Итого | E17: =SUM(E6:E16) -> 53811.08 | F17: =SUM(F6:F16) -> 41811.08 | G17: =SUM(G6:G16) -> 12000

Sheet Sanny 9524
A1: Содержание!A1
B3: 77 МН 9524 | C3: SY0151СС28158/SANWS6706NK004367 | D3: Колесный экскаватор SANY,SY155W (158)
A5: Дата документа | B5: номер документа | C5: поставщик | D5: вид работ | E5: стоимость общая | F5: стоимость запасных частей | G5: стоимость работ
A6: 46251 | B6: Т2615 | C6: АСТ Комплект | D6: корпус бортовой | E6: =SUM(F6:G6) -> 65548 | F6: 65548
E7: =SUM(F7:G7) -> 0
E8: =SUM(F8:G8) -> 0
E9: =SUM(F9:G9) -> 0
E10: =SUM(F10:G10) -> 0
A11: Итого | E11: =SUM(E6:E10) -> 65548 | F11: =SUM(F6:F10) -> 65548 | G11: =SUM(G6:G10) -> 0

Sheet Sanny 9525
A1: Содержание!A1
B3: 77 МН 9525 | C3: SY0151CC25368/SANW6706NK004361 | D3: Колесный экскаватор SANY,SY155W(368) | E3: 2022
A5: Дата документа | B5: номер документа | C5: поставщик | D5: вид работ | E5: стоимость общая | F5: стоимость запасных частей | G5: стоимость работ
A6: 45720 | B6: ААМС-001833 | C6: ООО АСТ | D6: зубья для ковша | E6: =SUM(F6:G6) -> 7750 | F6: 7750
A7: 46105 | B7: ААМС-2644 | C7: АСТ | D7: фара | E7: =SUM(F7:G7) -> 7296 | F7: 7296
A8: 46224 | B8: 2275 | C8: АСТ Комплект | D8: корпус бортовой передачи | E8: =SUM(F8:G8) -> 119123 | F8: 119123
A9: 46251 | B9: 2615 | C9: АСТ Комплект | D9: корпус бортовой передачи | E9: =SUM(F9:G9) -> 65548 | F9: 65548
E10: =SUM(F10:G10) -> 0
E11: =SUM(F11:G11) -> 0
E12: =SUM(F12:G12) -> 0
E13: =SUM(F13:G13) -> 0
E14: =SUM(F14:G14) -> 0
E15: =SUM(F15:G15) -> 0
E16: =SUM(F16:G16) -> 0
E17: =SUM(F17:G17) -> 0
E18: =SUM(F18:G18) -> 0
A19: Итого | E19: =SUM(E6:E18) -> 199717 | F19: =SUM(F6:F18) -> 199717 | G19: =SUM(G6:G18) -> 0

Sheet Sanny 6820
A1: Содержание!A1
B3: 77 РМ 6820 | C3: SY0151CC16818/SANWS6706NK004059 | D3: Экскаватор SANY,SY155W | E3: 2022
A5: Дата документа | B5: номер документа | C5: поставщик | D5: вид работ | E5: стоимость общая | F5: стоимость запасных частей | G5: стоимость работ
A6: 46104 | B6: ААМС-2565 | C6: АСТ | D6: палец и зуб ковша | E6: =SUM(F6:G6) -> 9200 | F6: 9200
A7: 46105 | B7: ААМС-2644 | C7: АСТ | D7: задний фонарь | E7: =SUM(F7:G7) -> 3480 | F7: 3480
E8: =SUM(F8:G8) -> 0
E9: =SUM(F9:G9) -> 0
E10: =SUM(F10:G10) -> 0
A11: Итого | E11: =SUM(E6:E10) -> 12680 | F11: =SUM(F6:F10) -> 12680 | G11: =SUM(G6:G10) -> 0

Sheet Sanny 7013
A1: Содержание!A1
B3: 77 ММ 7013 | C3: SY0151CC25018/SANWS6701NK004339 | D3: Самоходная машина SANY SY155W | E3: 2022
A5: Дата документа | B5: номер документа | C5: поставщик | D5: вид работ | E5: стоимость общая | F5: стоимость запасных частей | G5: стоимость работ
E6: =SUM(F6:G6) -> 0
E7: =SUM(F7:G7) -> 0
E8: =SUM(F8:G8) -> 0
E9: =SUM(F9:G9) -> 0
E10: =SUM(F10:G10) -> 0
A11: Итого | E11: =SUM(E6:E10) -> 0 | F11: =SUM(F6:F10) -> 0 | G11: =SUM(G6:G10) -> 0

Sheet CAT 318
A1: Содержание!A1
B3: 77 РК 7946 | C3: CAT0318CJDAH00858 | D3: Экскаватор Caterpiliar Inc.318CL | E3: 2005
A5: Дата документа | B5: номер документа | C5: поставщик | D5: вид работ | E5: стоимость общая | F5: стоимость запасных частей | G5: стоимость работ
A6: 45604 | B6: 0115 | C6: ООО АТМ групп | D6: ремонт двигателя с з\ч | E6: =SUM(F6:G6) -> 1045130 | F6: 1045130
A7: 45705 | B7: УТ-181 | C7: ООО Экстам | D7: Муфта | E7: =SUM(F7:G7) -> 9920 | F7: 9920
A8: 45739 | B8: 22 | C8: ООО АТМ групп | D8: монтаж двигателя | E8: =SUM(F8:G8) -> 20000 | G8: 20000
A9: 46245 | B9: УТ-3744 | C9: ООО Селтекс | D9: прокладки ГБЦ | E9: =SUM(F9:G9) -> 10880 | F9: 10880
A10: 46114 | B10: 40 | C10: ИП Тапал | D10: диагностика работы двигателя | E10: =SUM(F10:G10) -> 15000 | G10: 15000
A11: 46118 | B11: 137 | C11: Гидро-пневмогрупп | D11: ремонт гидронасоса | E11: =SUM(F11:G11) -> 150000 | G11: 150000
A12: 46129 | B12: 26 | C12: АТМ Групп | D12: комплект прокладок | E12: =SUM(F12:G12) -> 33050 | F12: 33050
A13: 46245 | B13: 4126 | C13: Селтекс | D13: прокладки ГБЦ | E13: =SUM(F13:G13) -> 10880 | F13: 10880
A14: 46255 | B14: 1116 | C14: Лидер Партс | D14: зубы ковша | E14: =SUM(F14:G14) -> 0
E15: =SUM(F15:G15) -> 0
E16: =SUM(F16:G16) -> 0
E17: =SUM(F17:G17) -> 0
E18: =SUM(F18:G18) -> 0
E19: =SUM(F19:G19) -> 0
E20: =SUM(F20:G20) -> 0
E21: =SUM(F21:G21) -> 0
A22: Итого | E22: =SUM(E6:E21) -> 1294860 | F22: =SUM(F6:F21) -> 1109860 | G22: =SUM(G6:G21) -> 185000

Sheet Sanny 330
A1: Содержание!A1
D3: Экскаватор Sany 330 | E3: 2021
A5: Дата документа | B5: номер документа | C5: поставщик | D5: вид работ | E5: стоимость общая | F5: стоимость запасных частей | G5: стоимость работ
A6: 46108 | B6: ААМС-2782 | C6: АСТ | D6: Диагностика | E6: =SUM(F6:G6) -> 36426 | G6: 36426
A7: 46134 | B7: 178 | C7: Гтдротехтрейд | D7: ремонт гидроцилиндров стрелы | E7: =SUM(F7:G7) -> 273013 | G7: 273013
A8: 46150 | B8: 24206 | C8: АктиоРус | D8: валы редуктора и гидромотора | E8: =SUM(F8:G8) -> 40001.36 | F8: 40001.36
A9: 46148 | B9: 23576 | C9: АктиоРус | D9: Дапуконы бортовой передачи | E9: =SUM(F9:G9) -> 40001.36 | F9: 40001.36
A10: 46171 | B10: 28453 | C10: АктиоРус | D10: стартер | E10: =SUM(F10:G10) -> 21000.47 | F10: 21000.47
E11: =SUM(F11:G11) -> 0
E12: =SUM(F12:G12) -> 0
E13: =SUM(F13:G13) -> 0
E14: =SUM(F14:G14) -> 0
E15: =SUM(F15:G15) -> 0
E16: =SUM(F16:G16) -> 0
E17: =SUM(F17:G17) -> 0
E18: =SUM(F18:G18) -> 0
A19: Итого | E19: =SUM(E6:E18) -> 410442.19 | F19: =SUM(F6:F18) -> 101003.19 | G19: =SUM(G6:G18) -> 309439

Sheet Liugong
A1: Содержание!A1
B3: 77 ММ 7012 | C3: LGJ6614ETNR 059175 | D3: Каток вибрационный LIUGONG CLG6614E | E3: 2022
A5: Дата документа | B5: номер документа | C5: поставщик | D5: вид работ | E5: стоимость общая | F5: стоимость запасных частей | G5: стоимость работ | H5: пробег (наработка)
A6: 46201 | D6: Полное ТО с заменой ГЖ | E6: =SUM(F6:G6) -> 0 | H6: 2350
A7: 46171 | B7: 28232 | C7: АктиоРус | D7: прокладка ГБЦ | E7: =SUM(F7:G7) -> 9775.25 | F7: 9775.25
E8: =SUM(F8:G8) -> 0
E9: =SUM(F9:G9) -> 0
E10: =SUM(F10:G10) -> 0
A11: Итого | E11: =SUM(E6:E10) -> 9775.25 | F11: =SUM(F6:F10) -> 9775.25 | G11: =SUM(G6:G10) -> 0

Sheet Ammann 4897
A1: Содержание!A1
B3: 77 РА 4897 | C3: 6152062 | D3: каток дорожный самоходный вибрационный AMMANN, ARX 26 К | E3: 2019
A5: Дата документа | B5: номер документа | C5: поставщик | D5: вид работ | E5: стоимость общая | F5: стоимость запасных частей | G5: стоимость работ
E6: =SUM(F6:G6) -> 0
E7: =SUM(F7:G7) -> 0
E8: =SUM(F8:G8) -> 0
E9: =SUM(F9:G9) -> 0
E10: =SUM(F10:G10) -> 0
A11: Итого | E11: =SUM(E6:E10) -> 0 | F11: =SUM(F6:F10) -> 0 | G11: =SUM(G6:G10) -> 0

Sheet Amann 7057
A1: Содержание!A1
B3: 77 ММ 7057 | C3: ACZ16234EN3046027 | D3: Каток дорожный AMMANN ARX45-2 | E3: 2022
A5: Дата документа | B5: номер документа | C5: поставщик | D5: вид работ | E5: стоимость общая | F5: стоимость запасных частей | G5: стоимость работ
E6: =SUM(F6:G6) -> 0
E7: =SUM(F7:G7) -> 0
E8: =SUM(F8:G8) -> 0
E9: =SUM(F9:G9) -> 0
E10: =SUM(F10:G10) -> 0
A11: Итого | E11: =SUM(E6:E10) -> 0 | F11: =SUM(F6:F10) -> 0 | G11: =SUM(G6:G10) -> 0

Sheet Ammann 7011
A1: Содержание!A1
B3: 77 ММ 7011 | C3: АСZ16234PN3046467 | D3: Каток дорожный AMMANN ARX45-2 | E3: 2022
A5: Дата документа | B5: номер документа | C5: поставщик | D5: вид работ | E5: стоимость общая | F5: стоимость запасных частей | G5: стоимость работ
E6: =SUM(F6:G6) -> 0
E7: =SUM(F7:G7) -> 0
E8: =SUM(F8:G8) -> 0
E9: =SUM(F9:G9) -> 0
E10: =SUM(F10:G10) -> 0
A11: Итого | E11: =SUM(E6:E10) -> 0 | F11: =SUM(F6:F10) -> 0 | G11: =SUM(G6:G10) -> 0

Sheet Hamm 4698
A1: Содержание!A1
B3: 77 МО 4698 | C3: H1812561 | D3: Каток дорожный HD110 HAMM AG | E3: 2013
A5: Дата документа | B5: номер документа | C5: поставщик | D5: вид работ | E5: стоимость общая | F5: стоимость запасных частей | G5: стоимость работ
A6: 46104 | B6: 866 | C6: МСБ Групп | D6: замена стекол | E6: =SUM(F6:G6) -> 86050 | F6: 60050 | G6: 26000
A7: 46199 | B7: 2461 | C7: Мирдортехника | D7: водяной фильтр | E7: =SUM(F7:G7) -> 12812 | F7: 12812
E8: =SUM(F8:G8) -> 0
E9: =SUM(F9:G9) -> 0
E10: =SUM(F10:G10) -> 0
A11: Итого | E11: =SUM(E6:E10) -> 98862 | F11: =SUM(F6:F10) -> 72862 | G11: =SUM(G6:G10) -> 26000

Sheet Hamm 4897
A1: Содержание!A1
B3: 77 МН 4897 | C3: H1531477 | D3: СМ КАТОК HAMM HD 090V | E3: 2005
A5: Дата документа | B5: номер документа | C5: поставщик | D5: вид работ | E5: стоимость общая | F5: стоимость запасных частей | G5: стоимость работ
A6: 45638 | B6: 285 | C6: ООО Финк | D6: запчасти | E6: =SUM(F6:G6) -> 104814.6 | F6: 104814.6
A7: 45677 | B7: 125 | C7: ООО МСБ Групп | D7: Замена стекол | E7: =SUM(F7:G7) -> 36600 | F7: 27700 | G7: 8900
A8: 46238 | B8: 1495 | C8: ООО Каскад спецтехсервис | D8: стартер | E8: =SUM(F8:G8) -> 15600 | F8: 15600
A9: 46257 | B9: 363/4 | C9: Т-запчасти | D9: подкачка и фильтр | E9: =SUM(F9:G9) -> 3400 | F9: 3400
A10: 46171 | B10: 70 | C10: ВирСервис | D10: замена подшипника вальцов | E10: =SUM(F10:G10) -> 190000 | G10: 190000
A11: 46155 | B11: 426 | C11: Трак Юнит | D11: форсунки и насос водяной | E11: =SUM(F11:G11) -> 31508 | F11: 31508
E12: =SUM(F12:G12) -> 0
E13: =SUM(F13:G13) -> 0
E14: =SUM(F14:G14) -> 0
E15: =SUM(F15:G15) -> 0
E16: =SUM(F16:G16) -> 0
E17: =SUM(F17:G17) -> 0
E18: =SUM(F18:G18) -> 0
A19: Итого | E19: =SUM(F19:G19) -> 381922.6 | F19: =SUM(F6:F18) -> 183022.6 | G19: =SUM(G6:G18) -> 198900

Sheet ZDM 9579
A1: Содержание!A1
B3: 77 МН 9579 | C3: DM3425 | D3: Каток дорожный самоходный ZDM DM-10-VD | E3: 2024
A5: Дата документа | B5: номер документа | C5: поставщик | D5: вид работ | E5: стоимость общая | F5: стоимость запасных частей | G5: стоимость работ
E6: =SUM(F6:G6) -> 0
E7: =SUM(F7:G7) -> 0
E8: =SUM(F8:G8) -> 0
E9: =SUM(F9:G9) -> 0
E10: =SUM(F10:G10) -> 0
A11: Итого | E11: =SUM(E6:E10) -> 0 | F11: =SUM(F6:F10) -> 0 | G11: =SUM(G6:G10) -> 0

Sheet ZDM 9580
A1: Содержание!A1
B3: 77 МН 9580 | C3: DM3419 | D3: Каток дорожный самоходный ZDM ZDM-10-VC | E3: 2024
A5: Дата документа | B5: номер документа | C5: поставщик | D5: вид работ | E5: стоимость общая | F5: стоимость запасных частей | G5: стоимость работ
E6: =SUM(F6:G6) -> 0
E7: =SUM(F7:G7) -> 0
E8: =SUM(F8:G8) -> 0
E9: =SUM(F9:G9) -> 0
E10: =SUM(F10:G10) -> 0
A11: Итого | E11: =SUM(E6:E10) -> 0 | F11: =SUM(F6:F10) -> 0 | G11: =SUM(G6:G10) -> 0

Sheet BW 161
A1: Содержание!A1
B3: 77 МН 4901 | C3: 101920091188 | D3: СМ КАТОК Дорожный BW 161 AD-4 | E3: 2010
A5: Дата документа | B5: номер документа | C5: поставщик | D5: вид работ | E5: стоимость общая | F5: стоимость запасных частей | G5: стоимость работ
E6: =SUM(F6:G6) -> 0
E7: =SUM(F7:G7) -> 0
E8: =SUM(F8:G8) -> 0
E9: =SUM(F9:G9) -> 0
E10: =SUM(F10:G10) -> 0
A11: Итого | E11: =SUM(E6:E10) -> 0 | F11: =SUM(F6:F10) -> 0 | G11: =SUM(G6:G10) -> 0

Sheet Vogel 6821
A1: Содержание!A1
B3: 77 РВ 6821 | C3: 07191650 | D3: Асфальтоукладчик VOGEL SUPER 1900-2 6 метр | E3: 2011
A5: Дата документа | B5: номер документа | C5: поставщик | D5: вид работ | E5: стоимость общая | F5: стоимость запасных частей | G5: стоимость работ
A6: 45637 | B6: 281 | C6: ООО Финк | D6: запчасти | E6: =SUM(F6:G6) -> 763057.5 | F6: 763057.5
A7: 45747 | B7: 458679690 | C7: ООО А.П.Р. | D7: генератор | E7: =SUM(F7:G7) -> 30441.31 | F7: 30441.31
A8: 45747 | B8: 458705428 | C8: ООО А.П.Р. | D8: аккумуляторы | E8: =SUM(F8:G8) -> 30150 | F8: 30150
A9: 45761 | B9: 3010 | C9: ООО Арт Макс | D9: шпиндель | E9: =SUM(F9:G9) -> 95000 | F9: 95000
A10: 46141 | B10: 1001 | C10: ИП Цынцарь | D10: мойка радиаторов | E10: =SUM(F10:G10) -> 18000 | G10: 18000
